Workbook

Sheet Калькулятор
A1: СМЕТА НА ОДНОГО ГОСТЯ · Египет, январь 2027 · La Royal Event
A2: Жёлтое меняем руками, сиреневое считается само. Цены поставщиков названы устно; цены отелей взяты из открытых источников и предложением не являются.
A4: ИСХОДНЫЕ ДАННЫЕ
A5: Параметр | B5: Значение | C5: Ед. | F5: Комментарий
A6: Гостей | B6: 16 | C6: чел | F6: На это число делится всё
A7: Дней фрахта, вариант A | B7: 4 | C7: дней | F7: 25–29 января
A8: Дней фрахта, вариант B | B8: 5 | C8: дней | F8: 25–30 января
A9: Фрахт за день, USD | B9: 54500 | C9: USD | F9: ПРОВЕРИТЬ: за ночь фрахта или за календарный день
A10: Курс EUR/USD | B10: 1.1489 | F10: На 20.09.2026. На дату платежа будет другим
A11: Вознаграждение La Royal | B11: 0.15 | C11: доля | F11: Наценка на себестоимость
A13: РАСЧЁТ | F13: Все строки, кроме последней, считаются только по гостям
A14: Статья | B14: Цена | C14: Единица | D14: A, на гостя | E14: B, на гостя | F14: Что уточнить
A15: Фрахт судна | B15: =$B$9 | C15: за день | D15: =$B$9*$B$7/$B$6 | E15: =$B$9*$B$8/$B$6 | F15: ПРОВЕРИТЬ: «в день» — за ночь фрахта или за календарный день
A16: Филе: визит и показ | B16: 15000 | C16: EUR за группу | D16: =B16*$B$10/$B$6 | E16: =B16*$B$10/$B$6 | F16: Договор в евро. Входит ли лодка от Шеллала
A17: Ужин на острове Филе | B17: 150 | C17: на гостя | D17: =B17 | E17: =B17 | F17: Названо клиентом. Сверх 15 000 EUR за приватный вечер
A18: Завтрак в Khufu’s | B18: 90 | C18: на гостя | D18: =B18 | E18: =B18 | F18: Названо клиентом
A19: Большой Египетский музей | B19: 120 | C19: на гостя | D19: =B19 | E19: =B19 | F19: Индивидуальная экскурсия с трансфером. Названо клиентом
A20: Гиза: приватный доступ, одно посещение | B20: 3500 | C20: за посещение | D20: =B20*2/$B$6 | E20: =B20*2/$B$6 | F20: ПОДТВЕРЖДЕНО: приватное открытие для группы. Билеты НЕ входят, см. строку ниже
A21: Входной билет на плато Гизы | B21: 180 | C21: за билет | D21: =B21*2 | E21: =B21*2 | F21: 180 за билет. ПРОВЕРИТЬ: один билет на оба посещения или два
A22: Абу-Симбел самолётом | B22: 470 | C22: на гостя | D22: =B22 | E22: =B22 | F22: Обязательная часть для всех. Альтернатива по земле — см. лист «Абу-Симбел»
A23: Giza Palace, ночь | B23: 325 | C23: за номер за ночь | D23: =B23*2 | E23: =B23*2 | F23: Две ночи. Открытые источники 222–349. Запросить групповой тариф
A24: Steigenberger Nile Palace, ночь | B24: 170 | C24: за номер за ночь | D24: =B24 | E24: =B24 | F24: Открытые источники 120–176. Запросить групповой тариф
A25: Отель 29 января: Асуан (A) / Four Seasons 30-го (B) | B25: 250 | C25: на гостя | D25: =B25 | E25: =570 | F25: A: остров Элефантина, открытые источники 140–330. B: Four Seasons, 570 названо отелем
A26: Прощальный ужин в Four Seasons | B26: 250 | C26: на гостя | D26: =B26 | E26: =0 | F26: Net или ++? С надбавками 319. Только вариант A
A27: Ужин в Lucida | B27: 150 | C27: на гостя | D27: =B27 | E27: =B27 | F27: ПОДТВЕРЖДЕНО: 150 без алкоголя
A28: Питание в отелях вне названных ресторанов | B28: 200 | C28: на гостя | D28: =B28 | E28: =B28 | F28: Наша оценка на всю поездку: ужин 40–60, обед 25–35
A29: Полёт на шаре, две корзины | B29: 5000 | C29: за все корзины | D29: =B29/$B$6 | E29: =B29/$B$6 | F29: ПОДТВЕРЖДЕНО: две корзины, по 8 человек
A30: Нубийский ансамбль | B30: 650 | C30: за вечер | D30: =B30/$B$6 | E30: =B30/$B$6 | F30: Наша оценка 400–900. Публичных прайсов нет
A31: Гала-ужин на борту, вариант B | B31: 0 | C31: за группу | D31: =0 | E31: =B31/$B$6 | F31: ЦЕНЫ НЕТ. Меню, декор, музыка сверх пансиона
A32: Наземная программа 22–25 января | B32: 0 | C32: за группу | D32: =B32/$B$6 | E32: =B32/$B$6 | F32: ЦЕНЫ НЕТ. Гид, транспорт, билеты, GEM. Крупнейшая дыра в смете
A33: Перелёты Каир–Луксор и Асуан–Каир | B33: 250 | C33: на гостя | D33: =B33 | E33: =B33 | F33: ОЦЕНКА по открытым источникам: 140 + 110. Групповой тариф запрошен
A34: Прочее: meet & greet, fast track | B34: 0 | C34: на гостя | D34: =B34 | E34: =B34 | F34: ЦЕНЫ НЕТ
A35: Резерв на решения на месте | B35: 0 | C35: на гостя | D35: =B35 | E35: =B35 | F35: НЕ ЗАЛОЖЕН. Обычно 2–3 % от сметы. Ваше решение
A36: ПРОПУЩЕННЫЕ СТАТЬИ — итог с листа «Пропущено» | B36: =Пропущено!$B$19 | C36: за группу | D36: =B36/$B$6 | E36: =B36/$B$6 | F36: Двенадцать позиций, найденных при сверке. Пока нули
A37: КОМАНДА LA ROYAL | B37: =Команда!$B$22 | C37: за группу | D37: =B37*Команда!$B$24/$B$6 | E37: =B37*Команда!$B$24/$B$6 | F37: Переключатель «в себестоимость / из вознаграждения» — на листе «Команда»
A38: СЕБЕСТОИМОСТЬ НА ГОСТЯ | D38: =SUM(D15:D37) | E38: =SUM(E15:E37)
A39: Вознаграждение La Royal | D39: =D38*$B$11 | E39: =E38*$B$11
A40: ЦЕНА ДЛЯ ГОСТЯ | D40: =D38+D39 | E40: =E38+E39
A41: Вознаграждение со всей группы | D41: =D39*$B$6-Команда!$B$22*(1-Команда!$B$24) | E41: =E39*$B$6-Команда!$B$22*(1-Команда!$B$24) | F41: Если команда идёт из вознаграждения, её расходы вычитаются здесь
A42: Если 15 % считать долей в цене, а не наценкой | D42: =D38/(1-$B$11) | E42: =E38/(1-$B$11)
...

Sheet Команда
A1: КОМАНДА LA ROYAL: СВОИ РАСХОДЫ
A2: Четыре-пять человек сопровождают группу всю поездку. На судне живут без доплаты: борт зафрахтован целиком. В Каире размещаются сами. На выезды идут не в полном составе.
A4: Параметр | B4: Значение | D4: Комментарий
A5: Человек в команде | B5: 4 | D5: Всего в поездке
A6: Человек в номере | B6: 2 | D6: 2 = по двое. 1 = одноместно, дороже
A7: Едет на выезды | B7: 2 | D7: Абу-Симбел и рестораны — не весь состав
A8: Отель в Каире, за номер | B8: 90 | D8: Свой отель, не Giza Palace
A9: Отель в Луксоре, за номер | B9: 170 | D9: С группой
A10: Отель 29-го, за номер | B10: 570 | D10: 570 = Four Seasons (B). Для варианта A ставим 250
A11: Питание на берегу, на чел | B11: 120 | D11: За всю поездку. На борту бесплатно
A13: Статья | B13: USD | D13: Как считается
A14: Судно | B14: =0 | D14: Борт зафрахтован целиком — команда на борту без доплаты
A15: Каир, свой отель, 2 ночи | B15: =ROUNDUP($B$5/$B$6,0)*2*$B$8 | D15: Номеров × 2 ночи × цена
A16: Луксор, 1 ночь | B16: =ROUNDUP($B$5/$B$6,0)*$B$9 | D16: Номеров × цена
A17: Отель 29-го: Асуан 250 (A) или FS 570 (B) | B17: =ROUNDUP($B$5/$B$6,0)*$B$10 | D17: Номеров × цена. Для A поставить 250
A18: Абу-Симбел самолётом | B18: =$B$7*470 | D18: Летят не все
A19: Ужины вне борта: Lucida, Филе, Khufu, прощальный | B19: =$B$7*760+$B$7*360 | D19: рестораны 760 + билеты в Гизу 360
A20: Питание на берегу | B20: =$B$5*$B$11 | D20: Весь состав
A21: Внутренние перелёты команды | B21: =$B$5*250 | D21: Те же 250 на человека
A22: ИТОГО РАСХОДЫ КОМАНДЫ | B22: =SUM(B14:B21)
A23: На одного гостя | B23: =B22/Калькулятор!$B$6
A24: ПЕРЕКЛЮЧАТЕЛЬ: 1 = в себестоимость, 0 = из вознаграждения | B24: 1 | D24: 1 — клиент платит за сопровождение, не видя отдельной строки. 0 — содержим команду из своей комиссии.
A26: Рекомендация: 1. Сопровождение собственной командой — услуга, которая отличает вас от агентства с пакетом. Услуги входят в цену.

Sheet Вопросы поставщикам
A1: ШЕСТЬ ВОПРОСОВ, БЕЗ КОТОРЫХ СЧИТАТЬ НЕЛЬЗЯ
A3: № | B3: Вопрос | C3: Кому | D3: Сколько за этим стоит
A4: 1 | B4: «54 500 в день» — за ночь фрахта или за календарный день? Считается ли утро высадки оплачиваемым днём? | C4: Судовой оператор | D4: 54 500, то есть 3 406 на гостя
A5: 2 | B5: Наземная программа 22–25 января: гид, транспорт, билеты, GEM | C5: Принимающая компания | D5: Позиции в смете нет вообще
A6: 3 | B6: Групповой тариф: Каир — Луксор и Асуан — Каир | C6: Билетный агент / EgyptAir | D6: Два рейса на всю группу
A7: 4 | B7: Прощальный ужин в Four Seasons: 250 — net или ++? Минимальный счёт за приватную зону? | C7: Four Seasons | D7: Около 1 100 на группу
A8: 5 | B8: Филе: фиксируем курс? Входит ли лодка от Шеллала? Цена ужина на острове? | C8: Мара, Egypt & Africa Travel | D8: Разброс 1 100 плюс неизвестная
A9: 6 | B9: Групповой блок номеров на январь: Giza Palace и Steigenberger | C9: Отделы продаж отелей | D9: Наши 325 и 170 — из интернета, ±30 %. Письма готовы

Sheet Абу-Симбел
A1: АБУ-СИМБЕЛ: САМОЛЁТОМ ИЛИ ПО ЗЕМЛЕ
A2: Берём обязательной частью для всех. Здесь считается, во что обходится каждый способ и сколько экономит дорога.
A4: Строка | B4: Самолётом | C4: По земле | D4: Комментарий
A5: Стоимость перелёта, на человека | B5: 470 | C5: 0 | D5: 470 названо поставщиком
A6: Автобус с гидом на день, за машину | B6: 0 | C6: 600 | D6: ОЦЕНКА 400–800. Нужен запрос в принимающую компанию
A7: Время в дороге в одну сторону | B7: 0.7 | C7: 3.75 | D7: Часы. 280–290 км по пустынной трассе
A8: Весь день занят | B8: 0 | C8: 1 | D8: 1 = да. По земле день уходит целиком
A10: На одного гостя | B10: =B5 | C10: =C6/Калькулятор!$B$6
A11: ЭКОНОМИЯ ДОРОГИ, на гостя | B11: =B10-C10
A12: ЭКОНОМИЯ ДОРОГИ, на группу | B12: =(B10-C10)*Калькулятор!$B$6
A14: Входные билеты в храмы одинаковы в обоих случаях и сидят в наземной программе.
A15: ВНИМАНИЕ: по земле цена ФИКСИРОВАННАЯ за машину. Если делать это опцией, работает та же ловушка, что с шаром: чем меньше едет, тем дороже каждому.

Sheet Пропущено
A1: СТАТЬИ, НАЙДЕННЫЕ ПРИ СВЕРКЕ МАРШРУТА
A2: Прошли весь маршрут по дням и сверили с расчётом. Вот чего в нём не было. Заполняйте по мере получения цен — итог сам попадёт в себестоимость.
A4: Статья | B4: USD за группу | D4: Почему это возникает
A5: Дневные номера в Асуане 29-го (вариант A) | B5: 0 | D5: Судно освобождается в 05:15, рейс в Каир днём. Между ними 18 человек с чемоданами и негде ждать
A6: Трансферы 29 и 30 января | B6: 0 | D6: Наземная программа посчитана только на 22–25. Асуан и Каир в конце поездки не покрыты
A7: Багажная машина в дни переездов | B7: 0 | D7: 18 гостей — это 20+ чемоданов. В легковые машины они не входят
A8: Перевес багажа на внутренних рейсах | B8: 0 | D8: Норма EgyptAir 23 кг. На девятидневной поездке перевес почти гарантирован
A9: Русскоязычный египтолог на речную часть | B9: 0 | D9: Оператор обещает «гида» — почти наверняка англоязычного. Наш гид 25–29: каюта, питание, гонорар
A10: Фелюкка и остров Китченера 28-го | B10: 0 | D10: Стоит в программе, в судовой пакет не входит
A11: Асуан утром 30-го: обелиск, Элефантина, музей | B11: 0 | D11: Только вариант B. Билеты, гид, транспорт
A12: Абу-Симбел: входные билеты и автобус на месте | B12: 0 | D12: 470 — это только перелёт
A13: Банковские комиссии и конвертация | B13: 0 | D13: Платежи в EUR и USD. Обычно 1–3 % от оборота
A14: Подарки и welcome-набор в номера | B14: 0 | D14: Для поездки такого уровня ожидаемо гостями
A15: Чаевые береговой части | B15: 0 | D15: Во фрахт входят чаевые ЭКИПАЖУ. Водители, гиды, носильщики и лодочники на берегу — отдельно
A16: Фото- и видеосъёмка поездки | B16: 0 | D16: Если нужна. Не обсуждалось
A19: ИТОГО ПРОПУЩЕНО | B19: =SUM(B5:B16)
A20: На одного гостя | B20: =B19/Калькулятор!$B$6
A22: Отдельно от этого списка остаются семь крупных позиций на листе «Калькулятор»: наземная программа 22–25, перелёты, ужин на Филе, гала на борту, Khufu's, meet & greet и резерв.
